<?xml version="1.0"?>
<!-- ===================================================================================== -->
<!-- |    这份文件是机器人描述文件，它定义了人形机器人的肢体和关节的形态、运动方式以及运动限制。        | -->
<!-- |    作者：pandasar@2024.12, strtrek@2025.6       开源协议：Apache License 2.0         | -->
<!-- ===================================================================================== -->

<!-- 机器人大腿描述文件 -->
<robot xmlns:xacro="http://www.ros.org/wiki/xacro" name="robot_macros_thigh">

    <!-- 宏定义：机器人大腿（robot_thigh）【滚转（roll l: -10°～25° r: -25°～10°）偏航（yaw: -40°～40°）俯仰（pitch: -45°～105°）】） -->
    <xacro:macro name="robot_thigh" params="name base laterality color">
        <!-- 大腿滚转运动（roll l: -10°～25° r: -25°～10°） -->
        <!-- 部件描述 -->
        <link name="robot_${name}_${laterality}_roll_link">
            <!-- 可见描述 -->
            <visual>
                <origin xyz="0 0 0" rpy="0 0 0"/>
                <geometry><mesh filename="package://${my_robot}/meshes/Link_hip_${laterality}_roll.STL"/></geometry>
                <material name="${color}"/>
            </visual>
            <!-- 碰撞描述 -->
            <collision>
                <origin xyz="0 0 0" rpy="0 0 0"/>
                <geometry><mesh filename="package://${my_robot}/meshes/Link_hip_${laterality}_roll.STL"/></geometry>
            </collision>
            <!-- 动惯量描述 -->
            <inertial>
                <!-- 右侧肢体 -->
                <xacro:if value="${laterality == 'r'}">
                    <!-- 质心 -->
                    <origin rpy="0 0 0" xyz="0.075725 -0.0010616 0.016591"/>
                    <!-- 质量 -->
                    <mass value="2.4334"/>
                    <!-- 惯性矩阵 -->
                    <inertia ixx="0.0036961" ixy="-9E-07" ixz="0.0001644" iyy="0.0045067" iyz="6.3E-06" izz="0.0039063"/>
                </xacro:if>
                <!-- 左侧肢体 -->
                <xacro:if value="${laterality == 'l'}">
                    <!-- 质心 -->
                    <origin rpy="0 0 0" xyz="0.075725 -0.00093843 0.016591"/>
                    <!-- 质量 -->
                    <mass value="2.4334"/>
                    <!-- 惯性矩阵 -->
                    <inertia ixx="0.0034464" ixy="9E-07" ixz="0.0001904" iyy="0.0042569" iyz="-6.6E-06" izz="0.0039063"/>
                </xacro:if>
            </inertial>
        </link>
        <!-- 关节描述 -->
        <joint name="robot_${name}_${laterality}_roll_joint" type="revolute">
            <!-- 父连接 -->
            <parent link="robot_${base}_link"/>
            <!-- 子连接 -->
            <child link="robot_${name}_${laterality}_roll_link"/>
            <!-- 右侧肢体 -->
            <xacro:if value="${laterality == 'r'}">
                <!-- 关节运动原点 -->
                <origin rpy="0 0 0" xyz="-0.0875 -0.12 -0.069"/>
                <!-- 关节运动轴位 -->
                <axis xyz="1 0 0"/>
                <!-- 关节运动限位 滚转（roll: -25°～10°） -->
                <limit effort="320" lower="-0.43633" upper="0.17453" velocity="20.94"/>
            </xacro:if>
            <!-- 左侧肢体 -->
            <xacro:if value="${laterality == 'l'}">
                <!-- 关节运动原点 -->
                <origin rpy="0 0 0" xyz="-0.0875 0.12 -0.069"/>
                <!-- 关节运动轴位 -->
                <axis xyz="1 0 0"/>
                <!-- 关节运动限位 滚转（roll: -10°～25°） -->
                <limit effort="320" lower="-0.17453" upper="0.43633" velocity="20.94"/>
            </xacro:if>
        </joint>

        <!-- 大腿偏航运动（yaw: -40°～40°） -->
        <!-- 部件描述 -->
        <link name="robot_${name}_${laterality}_yaw_link">
            <!-- 可见描述 -->
            <visual>
                <origin xyz="0 0 0" rpy="0 0 0"/>
                <geometry><mesh filename="package://${my_robot}/meshes/Link_hip_${laterality}_yaw.STL"/></geometry>
                <material name="${color}"/>
            </visual>
            <!-- 碰撞描述 -->
            <collision>
                <origin xyz="0 0 0" rpy="0 0 0"/>
                <geometry><mesh filename="package://${my_robot}/meshes/Link_hip_${laterality}_yaw.STL"/></geometry>
            </collision>
            <!-- 动惯量描述 -->
            <inertial>
                <!-- 右侧肢体 -->
                <xacro:if value="${laterality == 'r'}">
                    <!-- 质心 -->
                    <origin rpy="0 0 0" xyz="-3.0911E-08 -0.0071356 -0.10063"/>
                    <!-- 质量 -->
                    <mass value="3.4303"/>
                    <!-- 惯性矩阵 -->
                    <inertia ixx="0.0077365" ixy="0" ixz="0" iyy="0.0080807" iyz="0.0001167" izz="0.006641"/>
                </xacro:if>
                <!-- 左侧肢体 -->
                <xacro:if value="${laterality == 'l'}">
                    <!-- 质心 -->
                    <origin rpy="0 0 0" xyz="-3.1716E-08 0.0071358 -0.10063"/>
                    <!-- 质量 -->
                    <mass value="3.4304"/>
                    <!-- 惯性矩阵 -->
                    <inertia ixx="0.0077365" ixy="0" ixz="0" iyy="0.0080807" iyz="-0.0001167" izz="0.0066409"/>
                </xacro:if>
            </inertial>
        </link>
        <!-- 关节描述 -->
        <joint name="robot_${name}_${laterality}_yaw_joint" type="revolute">
            <!-- 父连接 -->
            <parent link="robot_${name}_${laterality}_roll_link"/>
            <!-- 子连接 -->
            <child link="robot_${name}_${laterality}_yaw_link"/>
            <!-- 右侧肢体 -->
            <xacro:if value="${laterality == 'r'}">
                <!-- 关节运动原点 -->
                <origin rpy="0 0 0" xyz="0.08225 -0.001 -0.01"/>
                <!-- 关节运动轴位 -->
                <axis xyz="0 0 1"/>
                <!-- 关节运动限位（yaw: -40°～40°） -->
                <limit effort="160" lower="-0.69813" upper="0.69813" velocity="19.63"/>
            </xacro:if>
            <!-- 左侧肢体 -->
            <xacro:if value="${laterality == 'l'}">
                <!-- 关节运动原点 -->
                <origin rpy="0 0 0" xyz="0.08225 -0.001 -0.01"/>
                <!-- 关节运动轴位 -->
                <axis xyz="0 0 1"/>
                <!-- 关节运动限位（yaw: -40°～40°） -->
                <limit effort="160" lower="-0.69813" upper="0.69813" velocity="19.63"/>
            </xacro:if>
        </joint>

        <!-- 大腿俯仰运动（pitch: -45°～105°） -->
        <!-- 部件描述 -->
        <link name="robot_${name}_${laterality}_link">
            <!-- 可见描述 -->
            <visual>
                <origin xyz="0 0 0" rpy="0 0 0"/>
                <geometry><mesh filename="package://${my_robot}/meshes/Link_hip_${laterality}_pitch.STL"/></geometry>
                <material name="${color}"/>
            </visual>
            <!-- 碰撞描述 -->
            <collision>
                <origin xyz="0 0 0" rpy="0 0 0"/>
                <geometry><mesh filename="package://${my_robot}/meshes/Link_hip_${laterality}_pitch.STL"/></geometry>
            </collision>
            <!-- 动惯量描述 -->
            <inertial>
                <!-- 右侧肢体 -->
                <xacro:if value="${laterality == 'r'}">
                    <!-- 质心 -->
                    <origin rpy="0 0 0" xyz="0.0010856 -0.05497 -0.14535"/>
                    <!-- 质量 -->
                    <mass value="5.2378"/>
                    <!-- 惯性矩阵 -->
                    <inertia ixx="0.043457" ixy="0.0002478" ixz="-0.0007626" iyy="0.037801" iyz="-0.0007431" izz="0.015183"/>
                </xacro:if>
                <!-- 左侧肢体 -->
                <xacro:if value="${laterality == 'l'}">
                    <!-- 质心 -->
                    <origin rpy="0 0 0" xyz="0.0010856 0.05497 -0.14535"/>
                    <!-- 质量 -->
                    <mass value="5.2378"/>
                    <!-- 惯性矩阵 -->
                    <inertia ixx="0.043457" ixy="-0.0002479" ixz="-0.0007626" iyy="0.037801" iyz="0.0007431" izz="0.015183"/>
                </xacro:if>
            </inertial>
        </link>
        <!-- 关节描述 -->
        <joint name="robot_${name}_${laterality}_pitch_joint" type="revolute">
            <!-- 父连接 -->
            <parent link="robot_${name}_${laterality}_yaw_link"/>
            <!-- 子连接 -->
            <child link="robot_${name}_${laterality}_link"/>
            <!-- 右侧肢体 -->
            <xacro:if value="${laterality == 'r'}">
                <!-- 关节运动原点 -->
                <origin rpy="0 0 0" xyz="0 0.03675 -0.1055"/>
                <!-- 关节运动轴位 -->
                <axis xyz="0 -1 0"/>
                <!-- 关节运动限位（pitch: -45°～105°） -->
                <limit effort="396" lower="-0.78540" upper="1.83260" velocity="19.16"/>
            </xacro:if>
            <!-- 左侧肢体 -->
            <xacro:if value="${laterality == 'l'}">
                <!-- 关节运动原点 -->
                <origin rpy="0 0 0" xyz="0 -0.03675 -0.1055"/>
                <!-- 关节运动轴位 -->
                <axis xyz="0 -1 0"/>
                <!-- 关节运动限位（pitch: -45°～105°） -->
                <limit effort="396" lower="-0.78540" upper="1.83260" velocity="19.16"/>
            </xacro:if>
        </joint>

    </xacro:macro>

</robot>