<?xml version="1.0"?>
<!-- ===================================================================================== -->
<!-- |    这份文件是机器人描述文件，它定义了人形机器人的肢体和关节的形态、运动方式以及运动限制。       | -->
<!-- |    作者：pandasar@2024.12, strtrek@2025.6       开源协议：Apache License 2.0        | -->
<!-- ===================================================================================== -->

<!-- 机器人头部描述文件 -->
<robot xmlns:xacro="http://www.ros.org/wiki/xacro" name="robot_macros_neck">
    
    <!-- 宏定义：机器人头部（robot_head）【偏航（yaw: -90°～90°）俯仰（pitch: -45°～45°）】 -->
    <xacro:macro name="robot_head" params="name base color">
        <!-- 头部偏航运动（yaw: -90°～90°） -->
        <!-- 部件描述 -->
        <link name="robot_${name}_yaw_link">
            <!-- 可见描述 -->
            <visual>
                <origin xyz="0 0 0" rpy="0 0 0"/>
                <geometry><mesh filename="package://${my_robot}/meshes/Link_head_yaw.STL"/></geometry>
                <material name="${color}"/>
            </visual>
            <!-- 碰撞描述 -->
            <collision>
                <origin xyz="0 0 0" rpy="0 0 0"/>
                <geometry><mesh filename="package://${my_robot}/meshes/Link_head_yaw.STL"/></geometry>
            </collision>
            <!-- 动惯量描述 -->
            <inertial>
                <!-- 质心 -->
                <origin rpy="0 0 0" xyz="4.6974E-12 -0.0020814 0.044801"/>
                <!-- 质量 -->
                <mass value="0.84249"/>
                <!-- 惯性矩阵 -->
                <inertia ixx="0.000629" ixy="1.2848E-14" ixz="-1.5461E-10" iyy="0.0007003" iyz="-6.5E-06" izz="0.0005541"/>
            </inertial>
        </link>
        <!-- 关节描述 -->
        <joint name="robot_${name}_yaw_joint" type="revolute">
            <!-- 父连接 -->
            <parent link="robot_${base}_link"/>
            <!-- 子连接 -->
            <child link="robot_${name}_yaw_link"/>
            <!-- 关节运动原点 -->
            <origin rpy="0 0 0" xyz="0.009 0 0.4064"/>
            <!-- 关节轴位 -->
            <axis xyz="0 0 1"/>
            <!-- 关节限位 偏航（yaw: -90°～90°） -->
            <limit effort="26" lower="-1.5708" upper="1.5708" velocity="109.8"/>    
        </joint>    

        <!-- 头部俯仰运动（pitch: -45°～45°） -->
        <!-- 部件描述 -->
        <link name="robot_${name}_link">
            <!-- 可见描述 -->
            <visual>
                <origin xyz="0 0 0" rpy="0 0 0"/>
                <geometry><mesh filename="package://${my_robot}/meshes/Link_head_pitch.STL"/></geometry>
                <material name="${color}"/>
            </visual>
            <!-- 碰撞描述 -->
            <collision>
                <origin xyz="0 0 0" rpy="0 0 0"/>
                <geometry><mesh filename="package://${my_robot}/meshes/Link_head_pitch.STL"/></geometry>
            </collision>
            <!-- 动惯量描述 -->
            <inertial>
                <!-- 质心 -->
                <origin rpy="0 0 0" xyz="0.020569 0.033004 0.125"/>
                <!-- 质量 -->
                <mass value="1.3943"/>
                <!-- 惯性矩阵 -->
                <inertia ixx="0.0060059" ixy="9.4E-06" ixz="-0.0007564" iyy="0.00629" iyz="1.03E-05" izz="0.0048569"/>
            </inertial>
        </link>
        <!-- 关节描述 -->
        <joint name="robot_${name}_pitch_joint" type="revolute">
            <!-- 父连接 -->
            <parent link="robot_${name}_yaw_link"/>
            <!-- 子连接 -->
            <child link="robot_${name}_link"/>
            <!-- 关节运动原点 -->
            <origin rpy="0 0 0" xyz="0 -0.0345999999999997 0.0484999999999999"/>
            <!-- 关节轴位 -->
            <axis xyz="0 -1 0"/>
            <!-- 关节限位 俯仰（pitch: -45°～45°） -->
            <limit effort="26" lower="-0.7854" upper="0.7854" velocity="109.8"/> 
        </joint>
        
    </xacro:macro>

</robot>