<?xml version="1.0"?>
<!-- ===================================================================================== -->
<!-- |    这份文件是机器人描述文件，它定义了人形机器人的肢体和关节的形态、运动方式以及运动限制。 | -->
<!-- |    作者：pandasar@2024.12, strtrek@2025.6       开源协议：Apache License 2.0        | -->
<!-- ===================================================================================== -->

<!-- 机器人手部描述文件 -->
<robot xmlns:xacro="http://www.ros.org/wiki/xacro" name="robot_macros_hand">

    <!-- 宏定义：机器人手部（robot_hand）【俯仰（pitch: -170°～170°）滚转（roll: -105°～105°）偏航（yaw: -60°～60°） -->
    <xacro:macro name="robot_hand" params="name base laterality color">

        <!-- 手部俯仰运动（pitch: -170°～170°） -->
        <!-- 部件描述 -->
        <link name="robot_${name}_${laterality}_pitch_link">
            <!-- 可见描述 -->
            <visual>
                <origin xyz="0 0 0" rpy="0 0 0"/>
                <geometry><mesh filename="package://${my_robot}/meshes/Link_arm_${laterality}_05.STL"/></geometry>
                <material name="${color}"/>
            </visual>
            <!-- 碰撞描述 -->
            <collision>
                <origin xyz="0 0 0" rpy="0 0 0"/>
                <geometry><mesh filename="package://${my_robot}/meshes/Link_arm_${laterality}_05.STL"/></geometry>
            </collision>
            <!-- 动惯量描述 -->
            <inertial>
                <!-- 右侧肢体 -->
                <xacro:if value="${laterality == 'r'}">
                    <!-- 质心 -->
                    <origin rpy="0 0 0" xyz="3.2712E-05 -0.068658 -0.00011178"/>
                    <!-- 质量 -->
                    <mass value="0.68976"/>
                    <!-- 惯性矩阵 -->
                    <inertia ixx="0.0025225" ixy="-4E-07" ixz="8E-07" iyy="0.0004487" iyz="3.1E-06" izz="0.0024111"/>
                </xacro:if>
                <!-- 左侧肢体 -->
                <xacro:if value="${laterality == 'l'}">
                    <!-- 质心 -->
                    <origin rpy="0 0 0" xyz="-3.2712E-05 0.068658 -0.00011178"/>
                    <!-- 质量 -->
                    <mass value="0.68976"/>
                    <!-- 惯性矩阵 -->
                    <inertia ixx="0.0025225" ixy="-4E-07" ixz="-8E-07" iyy="0.0004487" iyz="-3.1E-06" izz="0.0024111"/>
                </xacro:if>
            </inertial>
        </link>
        <!-- 关节描述 -->
        <joint name="robot_${name}_${laterality}_pitch_joint" type="revolute">
            <!-- 父连接 -->
            <parent link="robot_${base}_${laterality}_link"/>
            <!-- 子连接 -->
            <child link="robot_${name}_${laterality}_pitch_link"/>
            <!-- 右侧肢体 -->
            <xacro:if value="${laterality == 'r'}">
                <!-- 关节运动原点 -->
                <origin rpy="0 0 0" xyz="-0.0353 -0.1035 -0.024"/>
                <!-- 关节运动轴位 -->
                <axis xyz="0 -1 0"/>
                <!-- 关节运动限位 俯仰（pitch: -170°～170°） -->
                <limit effort="12.4" lower="-2.96706" upper="2.96706" velocity="6.28"/>
            </xacro:if>
            <!-- 左侧肢体 -->
            <xacro:if value="${laterality == 'l'}">
                <!-- 关节运动原点 -->
                <origin rpy="0 0 0" xyz="0.0353 0.1035 -0.024"/>
                <!-- 关节运动轴位 -->
                <axis xyz="0 1 0"/>
                <!-- 关节运动限位 俯仰（pitch: -170°～170°） -->
                <limit effort="12.4" lower="-2.96706" upper="2.96706" velocity="6.28"/>
            </xacro:if>
        </joint>

        <!-- 手部滚转运动（roll: -105°～105°） -->
        <!-- 部件描述 -->
        <link name="robot_${name}_${laterality}_roll_link">
            <!-- 可见描述 -->
            <visual>
                <origin xyz="0 0 0" rpy="0 0 0"/>
                <geometry><mesh filename="package://${my_robot}/meshes/Link_arm_${laterality}_06.STL"/></geometry>
                <material name="${color}"/>
            </visual>
            <!-- 碰撞描述 -->
            <collision>
                <origin xyz="0 0 0" rpy="0 0 0"/>
                <geometry><mesh filename="package://${my_robot}/meshes/Link_arm_${laterality}_06.STL"/></geometry>
            </collision>
            <!-- 动惯量描述 -->
            <inertial>
                <!-- 右侧肢体 -->
                <xacro:if value="${laterality == 'r'}">
                    <!-- 质心 -->
                    <origin rpy="0 0 0" xyz="0.026078 -8.9588E-07 0.0016637"/>
                    <!-- 质量 -->
                    <mass value="0.28"/>
                    <!-- 惯性矩阵 -->
                    <inertia ixx="0.0001456" ixy="-7.7026E-10" ixz="-2.1456E-07" iyy="0.00015693" iyz="-2.4102E-09" izz="0.00010498"/>
                </xacro:if>
                <!-- 左侧肢体 -->
                <xacro:if value="${laterality == 'l'}">
                    <!-- 质心 -->
                    <origin rpy="0 0 0" xyz="-0.0260776548825596 8.95877202866657E-07 0.00166373234012217"/>
                    <!-- 质量 -->
                    <mass value="0.280000012776158"/>
                    <!-- 惯性矩阵 -->
                    <inertia ixx="0.000145596926990102" ixy="-7.70263046256849E-10" ixz="2.14557176368931E-07" iyy="0.000156926535065694" iyz="2.41022657678511E-09" izz="0.000104981940665913"/>
                </xacro:if>
            </inertial>
        </link>
        <!-- 关节描述 -->
        <joint name="robot_${name}_${laterality}_roll_joint" type="revolute">
            <!-- 父连接 -->
            <parent link="robot_${name}_${laterality}_pitch_link"/>
            <!-- 子连接 -->
            <child link="robot_${name}_${laterality}_roll_link"/>
            <!-- 右侧肢体 -->
            <xacro:if value="${laterality == 'r'}">
                <!-- 关节运动原点 -->
                <origin rpy="0 0 0" xyz="-0.0265 -0.1965 0"/>
                <!-- 关节运动轴位 -->
                <axis xyz="1 0 0"/>
                <!-- 关节运动限位 滚转（roll: -105°～105°） -->
                <limit effort="12.4" lower="-1.8326" upper="1.8326" velocity="6.28"/>
            </xacro:if>
            <!-- 左侧肢体 -->
            <xacro:if value="${laterality == 'l'}">
                <!-- 关节运动原点 -->
                <origin rpy="0 0 0" xyz="0.0265 0.1965 0"/>
                <!-- 关节运动轴位 -->
                <axis xyz="-1 0 0"/>
                <!-- 关节运动限位 滚转（roll: -105°～105°） -->
                <limit effort="12.4" lower="-1.8326" upper="1.8326" velocity="6.28"/>
            </xacro:if>
        </joint>

        <!-- 手部偏航运动（yaw: -60°～60°） -->
        <!-- 部件描述 -->
        <link name="robot_${name}_${laterality}_link">
            <!-- 可见描述 -->
            <visual>
                <origin xyz="0 0 0" rpy="0 0 0"/>
                <geometry><mesh filename="package://${my_robot}/meshes/Link_arm_${laterality}_07.STL"/></geometry>
                <material name="${color}"/>
            </visual>
            <!-- 碰撞描述 -->
            <collision>
                <origin xyz="0 0 0" rpy="0 0 0"/>
                <geometry><mesh filename="package://${my_robot}/meshes/Link_arm_${laterality}_07.STL"/></geometry>
            </collision>
            <!-- 动惯量描述 -->
            <inertial>
                <!-- 右侧肢体 -->
                <xacro:if value="${laterality == 'r'}">
                    <!-- 质心 -->
                    <origin rpy="0 0 0" xyz="-0.007859 -0.15817 -0.027736"/>
                    <!-- 质量 -->
                    <mass value="0.61354"/>
                    <!-- 惯性矩阵 -->
                    <inertia ixx="0.0025969" ixy="4.65E-05" ixz="-0.0001089" iyy="0.0007306" iyz="-1.47E-05" izz="0.0030104"/>
                </xacro:if>
                <!-- 左侧肢体 -->
                <xacro:if value="${laterality == 'l'}">
                    <!-- 质心 -->
                    <origin rpy="0 0 0" xyz="-0.0077872 0.15705 -0.027733"/>
                    <!-- 质量 -->
                    <mass value="0.61354"/>
                    <!-- 惯性矩阵 -->
                    <inertia ixx="0.0025964" ixy="-4.66E-05" ixz="-0.0001089" iyy="0.0007306" iyz="1.47E-05" izz="0.00301"/>
                </xacro:if>
            </inertial>
        </link>
        <!-- 关节描述 -->
        <joint name="robot_${name}_${laterality}_yaw_joint" type="revolute">
            <!-- 父连接 -->
            <parent link="robot_${name}_${laterality}_roll_link"/>
            <!-- 子连接 -->
            <child link="robot_${name}_${laterality}_link"/>
            <!-- 右侧肢体 -->
            <xacro:if value="${laterality == 'r'}">
                <!-- 关节运动原点 -->
                <origin rpy="0 0 0" xyz="0.0265 0 0.0318"/>
                <!-- 关节运动轴位 -->
                <axis xyz="0 0 1"/>
                <!-- 关节运动限位 偏航（yaw: -60°～60°） -->
                <limit effort="12.4" lower="-1.04720" upper="1.04720" velocity="6.28"/>
            </xacro:if>
            <!-- 左侧肢体 -->
            <xacro:if value="${laterality == 'l'}">
                <!-- 关节运动原点 -->
                <origin rpy="0 0 0" xyz="-0.0265 0 0.0318"/>
                <!-- 关节运动轴位 -->
                <axis xyz="0 0 1"/>
                <!-- 关节运动限位 偏航（yaw: -60°～60°） -->
                <limit effort="12.4" lower="-1.04720" upper="1.04720" velocity="6.28"/>
            </xacro:if>
        </joint>

    </xacro:macro>

</robot>