<?xml version="1.0"?>
<!-- ===================================================================================== -->
<!-- |    这份文件是机器人描述文件，它定义了人形机器人的肢体和关节的形态、运动方式以及运动限制。        | -->
<!-- |    作者：pandasar@2024.12, strtrek@2025.6       开源协议：Apache License 2.0         | -->
<!-- ===================================================================================== -->

<!-- 机器人上臂描述文件 -->
<robot xmlns:xacro="http://www.ros.org/wiki/xacro" name="robot_macros_arm">

    <!-- 宏定义：机器人上臂（robot_arm）【俯仰（pitch: -170°～170°）滚转（roll: -105°～105°）】 -->
    <xacro:macro name="robot_arm" params="name base laterality color">
        <!-- 上臂俯仰运动（pitch: -170°～170°） -->
        <!-- 部件描述 -->
        <link name="robot_${name}_${laterality}_pitch_link">
            <!-- 可见描述 -->
            <visual>
                <origin xyz="0 0 0" rpy="0 0 0"/>
                <geometry><mesh filename="package://${my_robot}/meshes/Link_arm_${laterality}_01.STL"/></geometry>
                <material name="${color}"/>
            </visual>
            <!-- 碰撞描述 -->
            <collision>
                <origin xyz="0 0 0" rpy="0 0 0"/>
                <geometry><mesh filename="package://${my_robot}/meshes/Link_arm_${laterality}_01.STL"/></geometry>
            </collision>
            <!-- 动惯量描述 -->
            <inertial>
                <!-- 右侧肢体 -->
                <xacro:if value="${laterality == 'r'}">
                    <!-- 质心 -->
                    <origin rpy="0 0 0" xyz="0.0044946 -0.038294 -1.8744E-06"/>
                    <!-- 质量 -->
                    <mass value="0.75641"/>
                    <!-- 惯性矩阵 -->
                    <inertia ixx="0.00058712" ixy="-2.9803E-07" ixz="-5.8378E-09" iyy="0.00080305" iyz="3.6648E-08" izz="0.00084299"/>
                </xacro:if>
                <!-- 左侧肢体 -->
                <xacro:if value="${laterality == 'l'}">
                    <!-- 质心 -->
                    <origin rpy="0 0 0" xyz="-0.00449464987882542 0.0382942125981936 -1.874402432607E-06"/>
                    <!-- 质量 -->
                    <mass value="0.756406339732892"/>
                    <!-- 惯性矩阵 -->
                    <inertia ixx="0.000587115683146372" ixy="-2.98026052651538E-07" ixz="5.83781087215966E-09" iyy="0.000803052813361661" iyz="-3.66476835396106E-08" izz="0.000842985653484675"/>
                </xacro:if>
            </inertial>
        </link>
        <!-- 关节描述 -->
        <joint name="robot_${name}_${laterality}_pitch_joint" type="revolute">
            <!-- 父连接 -->
            <parent link="robot_${base}_link"/>
            <!-- 子连接 -->
            <child link="robot_${name}_${laterality}_pitch_link"/>
            <!-- 右侧肢体 -->
            <xacro:if value="${laterality == 'r'}">
                <!-- 关节运动原点 -->
                <origin rpy="0 0 0" xyz="0.004 -0.1616 0.3922"/>
                <!-- 关节运动轴位 -->
                <axis xyz="0 -1 0"/>
                <!-- 关节运动限位 俯仰（pitch: -170°～170°） -->
                <limit effort="80" lower="-2.96706" upper="2.96706" velocity="3.14"/>
            </xacro:if>
            <!-- 左侧肢体 -->
            <xacro:if value="${laterality == 'l'}">
                <!-- 关节运动原点 -->
                <origin rpy="0 0 0" xyz="0.004 0.1616 0.3922"/>
                <!-- 关节运动轴位 -->
                <axis xyz="0 1 0"/>
                <!-- 关节运动限位 俯仰（pitch: -170°～170°） -->
                <limit effort="80" lower="-2.96706" upper="2.96706" velocity="3.14"/>
            </xacro:if>
        </joint>

        <!-- 上臂滚转运动（roll: -105°～105°） -->
        <!-- 部件描述 -->
        <link name="robot_${name}_${laterality}_link">
            <!-- 可见描述 -->
            <visual>
                <origin xyz="0 0 0" rpy="0 0 0"/>
                <geometry><mesh filename="package://${my_robot}/meshes/Link_arm_${laterality}_02.STL"/></geometry>
                <material name="${color}"/>
            </visual>
            <!-- 碰撞描述 -->
            <collision>
                <origin xyz="0 0 0" rpy="0 0 0"/>
                <geometry><mesh filename="package://${my_robot}/meshes/Link_arm_${laterality}_02.STL"/></geometry>
            </collision>
            <!-- 动惯量描述 -->
            <inertial>
                <!-- 右侧肢体 -->
                <xacro:if value="${laterality == 'r'}">
                    <!-- 质心 -->
                    <origin rpy="0 0 0" xyz="0.042 -0.0674307499121858 -6.93889390390723E-18"/>
                    <!-- 质量 -->
                    <mass value="0.984999996273518"/>
                    <!-- 惯性矩阵 -->
                    <inertia ixx="0.0017309882399251" ixy="9.79515256436727E-20" ixz="3.63988309726277E-19" iyy="0.00115401958000568" iyz="-4.42134220053852E-19" izz="0.00226269324370836"/>
                </xacro:if>
                <!-- 左侧肢体 -->
                <xacro:if value="${laterality == 'l'}">
                    <!-- 质心 -->
                    <origin rpy="0 0 0" xyz="-0.042 0.0674307499121858 1.38777878078145E-17"/>
                    <!-- 质量 -->
                    <mass value="0.984999996273518"/>
                    <!-- 惯性矩阵 -->
                    <inertia ixx="0.0017309882399251" ixy="1.48322871384691E-19" ixz="1.94588987195478E-19" iyy="0.00115401958000568" iyz="6.15989345249147E-19" izz="0.00226269324370836"/>
                </xacro:if>
            </inertial>
        </link>
        <!-- 关节描述 -->
        <joint name="robot_${name}_${laterality}_roll_joint" type="revolute">
            <!-- 父连接 -->
            <parent link="robot_${name}_${laterality}_pitch_link"/>
            <!-- 子连接 -->
            <child link="robot_${name}_${laterality}_link"/>
            <!-- 右侧肢体 -->
            <xacro:if value="${laterality == 'r'}">
                <!-- 关节运动原点 -->
                <origin rpy="0 0 0" xyz="-0.042 -0.041 0"/>
                <!-- 关节运动轴位 -->
                <axis xyz="-1 0 0"/>
                <!-- 关节运动限位 滚转（roll: -105°～105°） -->
                <limit effort="80" lower="-1.83260" upper="1.83260" velocity="3.14"/>
            </xacro:if>
            <!-- 左侧肢体 -->
            <xacro:if value="${laterality == 'l'}">
                <!-- 关节运动原点 -->
                <origin rpy="0 0 0" xyz="0.042 0.041 0"/>
                <!-- 关节运动轴位 -->
                <axis xyz="-1 0 0"/>
                <!-- 关节运动限位 滚转（roll: -105°～105°）-->
                <limit effort="80" lower="-1.83260" upper="1.83260" velocity="3.14"/>
            </xacro:if>
        </joint>

    </xacro:macro>

</robot>